Workbook

Sheet COVER
B2: TOKENEQUITYX LTD
B3: INTEGRATED FINANCIAL MODEL
B4: Africa's Digital Capital Market Infrastructure | Harare, Zimbabwe
B7: MODEL DETAILS
B8: Model Version | C8: V1.0 — March 2026
B9: Prepared By | C9: TokenEquityX Ltd — Finance Team
B10: Reviewed By | C10: Richard Chimuka, CEO
B11: Projection Period | C11: FY2026 — FY2030 (5 years)
B12: Base Currency | C12: USD (United States Dollar)
B13: Units | C13: USD unless stated
B14: Fiscal Year End | C14: 31 December
B15: Model Type | C15: Three-statement integrated model with DCF valuation
B17: COLOUR CODING LEGEND
B18: Input / Assumption | C18: Hardcoded values — change these to model scenarios
B19: Formula / Calculation | C19: Calculated values — do not edit directly
B20: Cross-Sheet Link | C20: Values pulled from another sheet in this workbook
B21: Section Header | C21: Major section labels and subtotals
B23: SHEET INDEX
B24: ASSUMPTIONS | C24: All model inputs and scenario toggles — START HERE
B25: REVENUE | C25: Detailed revenue build by stream
B26: OPEX | C26: Detailed operating expense build by category
B27: P&L | C27: Integrated profit & loss statement (5-year)
B28: CASH FLOW | C28: Cash flow statement — operating, investing, financing
B29: BALANCE SHEET | C29: Balance sheet projection
B30: SCENARIOS | C30: Side-by-side Bear / Base / Bull scenario comparison
B31: VALUATION | C31: DCF valuation, terminal value, sensitivity tables
B32: KPIs | C32: Key performance indicators and operational metrics
B33: CHARTS | C33: Visual summary — revenue, EBITDA, cash, valuation
B36: This financial model is prepared for internal planning and investor engagement purposes. All projections are forward-looking estimates based on stated assumptions and are subject to material uncertainty. Actual results may differ significantly. This model does not constitute an offer of securities or investment advice.

Sheet ASSUMPTIONS
B1: TOKENEQUITYX — MODEL ASSUMPTIONS
B2: All blue cells are inputs. Change these to model different scenarios. Formulas reference these cells — do not hardcode values in other sheets.
B4: ASSUMPTION | C4: VALUE | D4: UNIT / FORMAT | E4: NOTES
B5: A. MACRO & MARKET ASSUMPTIONS
B6: USD / ZWG Exchange Rate (planning rate) | C6: 361 | D6: ZWG per USD | E6: Planning rate only — all model USD-denominated
B7: Annual USD Inflation Rate | C7: 0.03 | D7: % p.a. | E7: For real-terms sensitivity only
B8: Polygon Gas Cost per Transaction | C8: 0.001 | D8: USD per tx | E8: Average cost — negligible at current Polygon fees
B10: B. PLATFORM VOLUME ASSUMPTIONS
B11: Listed Assets — Year 1 (2026) | C11: 10 | D11: assets | E11: Conservative sandbox pilot target
B12: Listed Assets — Year 2 (2027) | C12: 35 | D12: assets | E12: Post-licence commercial launch
B13: Listed Assets — Year 3 (2028) | C13: 80 | D13: assets | E13: Full commercial operations
B14: Listed Assets — Year 4 (2029) | C14: 150 | D14: assets | E14: SADC expansion commencing
B15: Listed Assets — Year 5 (2030) | C15: 250 | D15: assets | E15: Pan-African scale
B17: Registered Investors — Year 1 | C17: 500 | D17: investors | E17: Institutional focus in sandbox phase
B18: Registered Investors — Year 2 | C18: 2500 | D18: investors | E18: Post-licence retail and institutional
B19: Registered Investors — Year 3 | C19: 8000 | D19: investors | E19: SADC market entry accelerates growth
B20: Registered Investors — Year 4 | C20: 20000 | D20: investors | E20: Multi-country investor base
B21: Registered Investors — Year 5 | C21: 45000 | D21: investors | E21: Continental scale
B23: Monthly Trading Volume — Year 1 (USD) | C23: 250000 | D23: USD/month | E23: Sandbox pilot — controlled volumes
B24: Monthly Trading Volume — Year 2 (USD) | C24: 1500000 | D24: USD/month | E24: Post-licence ramp-up
... B27: Monthly Trading Volume — Year 5 (USD) | C27: 60000000 | D27: USD/month | E27: Pan-African volumes
B29: C. REVENUE RATE ASSUMPTIONS
B30: Trading Fee Rate | C30: 0.005 | D30: % of trade value | E30: 0.50% per matched trade — both sides
B31: Issuance Fee Rate | C31: 0.0025 | D31: % of issuance value | E31: 0.25% of token offer value at launch
B32: Average Issuance Size (USD) | C32: 500000 | D32: USD | E32: Average value per new token issuance
B33: Annual Platform Fee per Asset (USD) | C33: 5000 | D33: USD per asset p.a. | E33: Annual listing and maintenance fee
B34: Valuation Service Fee per Submission (USD) | C34: 500 | D34: USD per submission | E34: Financial data pipeline processing fee
B35: Valuation Submissions per Asset per Year | C35: 4 | D35: submissions p.a. | E35: Quarterly data submissions per listed asset
B36: KYC Onboarding Fee per Investor (USD) | C36: 50 | D36: USD per investor | E36: One-time KYC processing fee
B37: White-Label Licence Fee — Year 2 (USD) | C37: 100000 | D37: USD p.a. | E37: First banking partner deployment
B38: White-Label Licence Fee — Year 3 (USD) | C38: 250000 | D38: USD p.a. | E38: Second banking partner + renewals
B39: White-Label Licence Fee — Year 4 (USD) | C39: 500000 | D39: USD p.a. | E39: SADC market deployments
B40: White-Label Licence Fee — Year 5 (USD) | C40: 900000 | D40: USD p.a. | E40: Pan-African licensing revenue
B41: Data & Analytics Revenue — Year 2 (USD) | C41: 30000 | D41: USD p.a. | E41: 5 institutional data subscribers @ avg USD 500/month
... B45: IFC Technical Assistance Grant — Year 1 (USD) | C45: 80000 | D45: USD one-time | E45: Stage-gated: 40K on sandbox application, 40K on approval
B47: D. OPERATING EXPENSE ASSUMPTIONS
B48: CEO Salary (from Year 2, USD p.a.) | C48: 36000 | D48: USD p.a. | E48: Richard Chimuka — market rate for Zimbabwe fintech CEO
B49: CTO Salary (from Year 2, USD p.a.) | C49: 36000 | D49: USD p.a. | E49: Leo Gaviao — Year 1 equity only
B50: Senior Full-Stack Developer (from Q2 Y1) | C50: 24000 | D50: USD p.a. | E50: First hire — platform development and maintenance
B51: Compliance Officer (from Q2 Y1) | C51: 18000 | D51: USD p.a. | E51: Required before live transactions — mandatory pre-condition
...

Sheet REVENUE
B1: TOKENEQUITYX — REVENUE MODEL
B2: Detailed revenue build by stream. All inputs from ASSUMPTIONS sheet. Green = cross-sheet links.
B4: REVENUE STREAM | C4: 2026A | D4: 2027E | E4: 2028E | F4: 2029E | G4: 2030E | H4: NOTES
B5: A. VOLUME DRIVERS
B6: Listed Assets | D6: =ASSUMPTIONS!C11 -> 10 | E6: =ASSUMPTIONS!C12 -> 35 | F6: =ASSUMPTIONS!C13 -> 80 | G6: =ASSUMPTIONS!C14 -> 150 | H6: =ASSUMPTIONS!C15 -> 250 | I6: From Assumptions — user-controlled input
B7: New Assets Listed (net) | D7: =D6 -> 10 | E7: =E6-D6 -> 25 | F7: =F6-E6 -> 45 | G7: =G6-F6 -> 70 | H7: =H6-G6 -> 100 | I7: Incremental new listings per year
B8: Registered Investors | D8: =ASSUMPTIONS!C17 -> 500 | E8: =ASSUMPTIONS!C18 -> 2500 | F8: =ASSUMPTIONS!C19 -> 8000 | G8: =ASSUMPTIONS!C20 -> 20000 | H8: =ASSUMPTIONS!C21 -> 45000 | I8: From Assumptions
B9: New Investors (net) | D9: =D8 -> 500 | E9: =E8-D8 -> 2000 | F9: =F8-E8 -> 5500 | G9: =G8-F8 -> 12000 | H9: =H8-G8 -> 25000 | I9: Incremental new investors
B10: Annual Trading Volume (USD) | D10: =ASSUMPTIONS!C23*12 -> 3000000 | E10: =ASSUMPTIONS!C24*12 -> 18000000 | F10: =ASSUMPTIONS!C25*12 -> 72000000 | G10: =ASSUMPTIONS!C26*12 -> 240000000 | H10: =ASSUMPTIONS!C27*12 -> 720000000 | I10: Monthly × 12
B11: Scenario Volume Multiplier | D11: =IF(ASSUMPTIONS!C84="Bear",ASSUMPTIONS!C85,IF(ASSUMPTIONS!C84="Bull",ASSUMPTIONS!C86,1)) -> 1 | E11: =IF(ASSUMPTIONS!C84="Bear",ASSUMPTIONS!C85,IF(ASSUMPTIONS!C84="Bull",ASSUMPTIONS!C86,1)) -> 1 | F11: =IF(ASSUMPTIONS!C84="Bear",ASSUMPTIONS!C85,IF(ASSUMPTIONS!C84="Bull",ASSUMPTIONS!C86,1)) -> 1 | G11: =IF(ASSUMPTIONS!C84="Bear",ASSUMPTIONS!C85,IF(ASSUMPTIONS!C84="Bull",ASSUMPTIONS!C86,1)) -> 1 | H11: =IF(ASSUMPTIONS!C84="Bear",ASSUMPTIONS!C85,IF(ASSUMPTIONS!C84="Bull",ASSUMPTIONS!C86,1)) -> 1 | I11: Bear=0.60x | Base=1.00x | Bull=1.50x of volume assumptions
B12: B. REVENUE BY STREAM
B13: 1. Trading Fees | D13: =ASSUMPTIONS!C23*12*ASSUMPTIONS!C30*D11 -> 15000 | E13: =ASSUMPTIONS!C24*12*ASSUMPTIONS!C30*E11 -> 90000 | F13: =ASSUMPTIONS!C25*12*ASSUMPTIONS!C30*F11 -> 360000 | G13: =ASSUMPTIONS!C26*12*ASSUMPTIONS!C30*G11 -> 1200000 | H13: =ASSUMPTIONS!C27*12*ASSUMPTIONS!C30*H11 -> 3600000 | I13: Annual trading volume × 0.50% fee rate × scenario multiplier
B14: 2. Issuance Fees | D14: =D7*ASSUMPTIONS!C32*ASSUMPTIONS!C31*D11 -> 12500 | E14: =(E7-D7)*ASSUMPTIONS!C32*ASSUMPTIONS!C31*E11 -> 18750 | F14: =(F7-E7)*ASSUMPTIONS!C32*ASSUMPTIONS!C31*F11 -> 25000 | G14: =(G7-F7)*ASSUMPTIONS!C32*ASSUMPTIONS!C31*G11 -> 31250 | H14: =(H7-G7)*ASSUMPTIONS!C32*ASSUMPTIONS!C31*H11 -> 37500 | I14: Net new assets × avg issuance size × 0.25% fee
B15: 3. Annual Platform Fees | D15: =D7*ASSUMPTIONS!C33 -> 50000 | E15: =E7*ASSUMPTIONS!C33 -> 125000 | F15: =F7*ASSUMPTIONS!C33 -> 225000 | G15: =G7*ASSUMPTIONS!C33 -> 350000 | H15: =H7*ASSUMPTIONS!C33 -> 500000 | I15: Total assets × USD 5,000 p.a. — NOT scenario-adjusted (fee is fixed per listing)
B16: 4. Valuation Services | D16: =D7*ASSUMPTIONS!C35*ASSUMPTIONS!C34 -> 20000 | E16: =E7*ASSUMPTIONS!C35*ASSUMPTIONS!C34 -> 50000 | F16: =F7*ASSUMPTIONS!C35*ASSUMPTIONS!C34 -> 90000 | G16: =G7*ASSUMPTIONS!C35*ASSUMPTIONS!C34 -> 140000 | H16: =H7*ASSUMPTIONS!C35*ASSUMPTIONS!C34 -> 200000 | I16: Assets × 4 submissions/year × USD 500
B17: 5. KYC Onboarding Fees | D17: =D9*ASSUMPTIONS!C36*D11 -> 25000 | E17: =(E9-D9)*ASSUMPTIONS!C36*E11 -> 75000 | F17: =(F9-E9)*ASSUMPTIONS!C36*F11 -> 175000 | G17: =(G9-F9)*ASSUMPTIONS!C36*G11 -> 325000 | H17: =(H9-G9)*ASSUMPTIONS!C36*H11 -> 650000 | I17: New investors × USD 50 onboarding fee
B18: 6. White-Label Licensing | D18: =0 -> 0 | E18: =ASSUMPTIONS!C37 -> 100000 | F18: =ASSUMPTIONS!C38 -> 250000 | G18: =ASSUMPTIONS!C39 -> 500000 | H18: =ASSUMPTIONS!C40 -> 900000 | I18: Banking partner deployments — Year 2 onwards
B19: 7. Data & Analytics | D19: =0 -> 0 | E19: =ASSUMPTIONS!C41 -> 30000 | F19: =ASSUMPTIONS!C42 -> 120000 | G19: =ASSUMPTIONS!C43 -> 350000 | H19: =ASSUMPTIONS!C44 -> 800000 | I19: Market data subscriptions — Year 2 onwards
B20: 8. IFC Technical Assistance Grant | D20: =ASSUMPTIONS!C45 -> 80000 | E20: =0 -> 0 | F20: =0 -> 0 | G20: =0 -> 0 | H20: =0 -> 0 | I20: One-time TA grant — Year 1 only
B21: TOTAL REVENUE | D21: =SUM(D13:D20) -> 202500 | E21: =SUM(E13:E20) -> 488750 | F21: =SUM(F13:F20) -> 1245000 | G21: =SUM(G13:G20) -> 2896250 | H21: =SUM(H13:H20) -> 6687500
B22: Revenue Growth YoY | D22: — | E22: =IFERROR((E21-D21)/D21,"-") -> 1.4135802 | F22: =IFERROR((F21-E21)/E21,"-") -> 1.5473146 | G22: =IFERROR((G21-F21)/F21,"-") -> 1.3263052 | H22: =IFERROR((H21-G21)/G21,"-") -> 1.3090203
B24: C. REVENUE MIX %
B25: Trading Fees % | D25: =IFERROR(D13/D21,0) -> 0.074074074 | E25: =IFERROR(E13/E21,0) -> 0.18414322 | F25: =IFERROR(F13/F21,0) -> 0.28915663 | G25: =IFERROR(G13/G21,0) -> 0.41432887 | H25: =IFERROR(H13/H21,0) -> 0.53831776
B26: Issuance Fees % | D26: =IFERROR(D14/D21,0) -> 0.061728395 | E26: =IFERROR(E14/E21,0) -> 0.038363171 | F26: =IFERROR(F14/F21,0) -> 0.020080321 | G26: =IFERROR(G14/G21,0) -> 0.010789814 | H26: =IFERROR(H14/H21,0) -> 0.0056074766
B27: Platform Fees % | D27: =IFERROR(D15/D21,0) -> 0.24691358 | E27: =IFERROR(E15/E21,0) -> 0.25575448 | F27: =IFERROR(F15/F21,0) -> 0.18072289 | G27: =IFERROR(G15/G21,0) -> 0.12084592 | H27: =IFERROR(H15/H21,0) -> 0.074766355
B28: Valuation Services % | D28: =IFERROR(D16/D21,0) -> 0.098765432 | E28: =IFERROR(E16/E21,0) -> 0.10230179 | F28: =IFERROR(F16/F21,0) -> 0.072289157 | G28: =IFERROR(G16/G21,0) -> 0.048338369 | H28: =IFERROR(H16/H21,0) -> 0.029906542
B29: KYC Fees % | D29: =IFERROR(D17/D21,0) -> 0.12345679 | E29: =IFERROR(E17/E21,0) -> 0.15345269 | F29: =IFERROR(F17/F21,0) -> 0.14056225 | G29: =IFERROR(G17/G21,0) -> 0.11221407 | H29: =IFERROR(H17/H21,0) -> 0.097196262
B30: White-Label % | D30: =IFERROR(D18/D21,0) -> 0 | E30: =IFERROR(E18/E21,0) -> 0.20460358 | F30: =IFERROR(F18/F21,0) -> 0.20080321 | G30: =IFERROR(G18/G21,0) -> 0.17263703 | H30: =IFERROR(H18/H21,0) -> 0.13457944
B31: Data & Analytics % | D31: =IFERROR(D19/D21,0) -> 0 | E31: =IFERROR(E19/E21,0) -> 0.061381074 | F31: =IFERROR(F19/F21,0) -> 0.096385542 | G31: =IFERROR(G19/G21,0) -> 0.12084592 | H31: =IFERROR(H19/H21,0) -> 0.11962617
B32: IFC Grant % | D32: =IFERROR(D20/D21,0) -> 0.39506173 | E32: =IFERROR(E20/E21,0) -> 0 | F32: =IFERROR(F20/F21,0) -> 0 | G32: =IFERROR(G20/G21,0) -> 0 | H32: =IFERROR(H20/H21,0) -> 0

Sheet OPEX
B1: TOKENEQUITYX — OPERATING EXPENSE MODEL
B2: All costs in USD. Inputs from ASSUMPTIONS sheet. Year 1 shows prorated costs for mid-year hires.
B4: COST ITEM | C4: 2026A | D4: 2027E | E4: 2028E | F4: 2029E | G4: 2030E | H4: NOTES
B5: A. PEOPLE COSTS
B6: CEO Salary | D6: =0 -> 0 | E6: =ASSUMPTIONS!C48 -> 36000 | F6: =ASSUMPTIONS!C48 -> 36000 | G6: =ASSUMPTIONS!C48 -> 36000 | H6: =ASSUMPTIONS!C48 -> 36000 | I6: Year 1 equity only; salary from Year 2
B7: CTO Salary | D7: =0 -> 0 | E7: =ASSUMPTIONS!C49 -> 36000 | F7: =ASSUMPTIONS!C49 -> 36000 | G7: =ASSUMPTIONS!C49 -> 36000 | H7: =ASSUMPTIONS!C49 -> 36000 | I7: Year 1 equity only; salary from Year 2
B8: Senior Full-Stack Developer | D8: =ASSUMPTIONS!C50*0.75 -> 18000 | E8: =ASSUMPTIONS!C50 -> 24000 | F8: =ASSUMPTIONS!C50 -> 24000 | G8: =ASSUMPTIONS!C50 -> 24000 | H8: =ASSUMPTIONS!C50 -> 24000 | I8: Q2 Year 1 hire — prorated 75%
B9: Compliance Officer | D9: =ASSUMPTIONS!C51*0.75 -> 13500 | E9: =ASSUMPTIONS!C51 -> 18000 | F9: =ASSUMPTIONS!C51 -> 18000 | G9: =ASSUMPTIONS!C51 -> 18000 | H9: =ASSUMPTIONS!C51 -> 18000 | I9: Q2 Year 1 hire — mandatory before live transactions
B10: Blockchain Developer | D10: =ASSUMPTIONS!C52*0.5 -> 12000 | E10: =ASSUMPTIONS!C52 -> 24000 | F10: =ASSUMPTIONS!C52 -> 24000 | G10: =ASSUMPTIONS!C52 -> 24000 | H10: =ASSUMPTIONS!C52 -> 24000 | I10: Q3 Year 1 hire — prorated 50%
B11: Business Development Manager | D11: =ASSUMPTIONS!C53*0.5 -> 9000 | E11: =ASSUMPTIONS!C53 -> 18000 | F11: =ASSUMPTIONS!C53 -> 18000 | G11: =ASSUMPTIONS!C53 -> 18000 | H11: =ASSUMPTIONS!C53 -> 18000 | I11: Q3 Year 1 hire — prorated 50%
B12: Finance & Operations Manager | D12: =ASSUMPTIONS!C54*0.25 -> 4500 | E12: =ASSUMPTIONS!C54 -> 18000 | F12: =ASSUMPTIONS!C54 -> 18000 | G12: =ASSUMPTIONS!C54 -> 18000 | H12: =ASSUMPTIONS!C54 -> 18000 | I12: Q4 Year 1 hire — prorated 25%
B13: Systems Administrator | D13: =ASSUMPTIONS!C55*0.25 -> 3750 | E13: =ASSUMPTIONS!C55 -> 15000 | F13: =ASSUMPTIONS!C55 -> 15000 | G13: =ASSUMPTIONS!C55 -> 15000 | H13: =ASSUMPTIONS!C55 -> 15000 | I13: Q4 Year 1 hire — prorated 25%
B14: Additional Headcount | D14: =0 -> 0 | E14: =ASSUMPTIONS!C56 -> 60000 | F14: =ASSUMPTIONS!C57 -> 120000 | G14: =ASSUMPTIONS!C58 -> 200000 | H14: =ASSUMPTIONS!C59 -> 350000 | I14: SADC and pan-African expansion hires
B15: Total People Costs | D15: =SUM(D6:D14) -> 60750 | E15: =SUM(E6:E14) -> 249000 | F15: =SUM(F6:F14) -> 309000 | G15: =SUM(G6:G14) -> 389000 | H15: =SUM(H6:H14) -> 539000
B16: B. TECHNOLOGY COSTS
B17: Cloud Infrastructure (API/DB/Storage) | D17: =ASSUMPTIONS!C61 -> 12000 | E17: =D17*(1+ASSUMPTIONS!C62) -> 15000 | F17: =E17*(1+ASSUMPTIONS!C62) -> 18750 | G17: =F17*(1+ASSUMPTIONS!C62) -> 23437.5 | H17: =G17*(1+ASSUMPTIONS!C62) -> 29296.875 | I17: Year 1 base; grows {A(ASS_CLOUD_GROWTH)} p.a.
B18: Polygon RPC Node | D18: =ASSUMPTIONS!C63 -> 3600 | E18: =D18*(1+ASSUMPTIONS!C64) -> 4680 | F18: =E18*(1+ASSUMPTIONS!C64) -> 6084 | G18: =F18*(1+ASSUMPTIONS!C64) -> 7909.2 | H18: =G18*(1+ASSUMPTIONS!C64) -> 10281.96 | I18: Scales with transaction volumes
B19: Monitoring, Alerting & DevOps Tools | D19: =3600 -> 3600 | E19: =3600 -> 3600 | F19: =5400 -> 5400 | G19: =7200 -> 7200 | H19: =9000 -> 9000 | I19: Grafana, PagerDuty, CI/CD pipelines
B20: Annual Penetration Test | D20: =ASSUMPTIONS!C71 -> 8000 | E20: =ASSUMPTIONS!C71 -> 8000 | F20: =ASSUMPTIONS!C71 -> 8000 | G20: =ASSUMPTIONS!C71 -> 8000 | H20: =ASSUMPTIONS!C71 -> 8000 | I20: Annual external cybersecurity assessment
B21: Miscellaneous Tech Licences & Tools | D21: =5000 -> 5000 | E21: =6000 -> 6000 | F21: =8000 -> 8000 | G21: =10000 -> 10000 | H21: =12000 -> 12000 | I21: Domain, SSL, productivity tools, developer licences
B22: Total Technology Costs | D22: =SUM(D17:D21) -> 32200 | E22: =SUM(E17:E21) -> 37280 | F22: =SUM(F17:F21) -> 46234 | G22: =SUM(G17:G21) -> 56546.7 | H22: =SUM(H17:H21) -> 68578.835
B23: C. REGULATORY & LEGAL COSTS
B24: Smart Contract Security Audit | D24: =ASSUMPTIONS!C65 -> 60000 | E24: =ASSUMPTIONS!C66 -> 15000 | F24: =ASSUMPTIONS!C66 -> 15000 | G24: =ASSUMPTIONS!C66 -> 15000 | H24: =ASSUMPTIONS!C66 -> 15000 | I24: Year 1: full audit; Year 2+: annual review
B25: Legal & Regulatory Fees | D25: =ASSUMPTIONS!C67 -> 25000 | E25: =ASSUMPTIONS!C68 -> 15000 | F25: =ASSUMPTIONS!C68 -> 15000 | G25: =ASSUMPTIONS!C68*1.2 -> 18000 | H25: =ASSUMPTIONS!C68*1.5 -> 22500 | I25: SECZ, RBZ, legal opinions; scales with SADC expansion
B26: Compliance & Regulatory Reporting | D26: =8000 -> 8000 | E26: =12000 -> 12000 | F26: =18000 -> 18000 | G26: =25000 -> 25000 | H26: =35000 -> 35000 | I26: Monthly SECZ sandbox reports, annual compliance audits
B27: SECZ / Exchange Licence Fees | D27: =0 -> 0 | E27: =5000 -> 5000 | F27: =8000 -> 8000 | G27: =10000 -> 10000 | H27: =12000 -> 12000 | I27: Annual regulatory licence fees — sandbox then full licence
B28: Total Regulatory & Legal | D28: =SUM(D24:D27) -> 93000 | E28: =SUM(E24:E27) -> 47000 | F28: =SUM(F24:F27) -> 56000 | G28: =SUM(G24:G27) -> 68000 | H28: =SUM(H24:H27) -> 84500
B29: D. SALES & MARKETING
B30: Brand & Digital Marketing | D30: =ASSUMPTIONS!C69*0.5 -> 7500 | E30: =D30*(1+ASSUMPTIONS!C70) -> 11250 | F30: =E30*(1+ASSUMPTIONS!C70) -> 16875 | G30: =F30*(1+ASSUMPTIONS!C70) -> 25312.5 | H30: =G30*(1+ASSUMPTIONS!C70) -> 37968.75 | I30: Website, LinkedIn, fintech press, thought leadership
B31: Conference & Events | D31: =ASSUMPTIONS!C69*0.3 -> 4500 | E31: =8000 -> 8000 | F31: =15000 -> 15000 | G31: =25000 -> 25000 | H31: =40000 -> 40000 | I31: SECZ symposia, AfDB forums, SADC fintech conferences
B32: Issuer Acquisition & BD | D32: =ASSUMPTIONS!C69*0.2 -> 3000 | E32: =10000 -> 10000 | F32: =20000 -> 20000 | G32: =35000 -> 35000 | H32: =60000 -> 60000 | I32: Direct sales and issuer origination costs
B33: Total Sales & Marketing | D33: =SUM(D30:D32) -> 15000 | E33: =SUM(E30:E32) -> 29250 | F33: =SUM(F30:F32) -> 51875 | G33: =SUM(G30:G32) -> 85312.5 | H33: =SUM(H30:H32) -> 137968.75
B34: E. GENERAL & ADMINISTRATIVE
B35: Office & Facilities | D35: =ASSUMPTIONS!C72*0.4 -> 4000 | E35: =D35*(1+ASSUMPTIONS!C73) -> 4800 | F35: =E35*(1+ASSUMPTIONS!C73) -> 5760 | G35: =F35*(1+ASSUMPTIONS!C73) -> 6912 | H35: =G35*(1+ASSUMPTIONS!C73) -> 8294.4 | I35: Harare office rent and utilities
B36: Travel & Subsistence | D36: =ASSUMPTIONS!C72*0.3 -> 3000 | E36: =5000 -> 5000 | F36: =10000 -> 10000 | G36: =20000 -> 20000 | H36: =35000 -> 35000 | I36: Regulatory meetings, investor roadshows, SADC travel
B37: Insurance | D37: =3000 -> 3000 | E37: =5000 -> 5000 | F37: =8000 -> 8000 | G37: =12000 -> 12000 | H37: =18000 -> 18000 | I37: PI insurance, cyber insurance, D&O insurance
B38: Finance, Audit & Accounting | D38: =8000 -> 8000 | E38: =12000 -> 12000 | F38: =15000 -> 15000 | G38: =18000 -> 18000 | H38: =22000 -> 22000 | I38: Annual statutory audit, bookkeeping, tax compliance
B39: Miscellaneous G&A | D39: =ASSUMPTIONS!C72*0.3 -> 3000 | E39: =D39*(1+ASSUMPTIONS!C73) -> 3600 | F39: =E39*(1+ASSUMPTIONS!C73) -> 4320 | G39: =F39*(1+ASSUMPTIONS!C73) -> 5184 | H39: =G39*(1+ASSUMPTIONS!C73) -> 6220.8 | I39: Sundry expenses
B40: Total G&A | D40: =SUM(D35:D39) -> 21000 | E40: =SUM(E35:E39) -> 30400 | F40: =SUM(F35:F39) -> 43080 | G40: =SUM(G35:G39) -> 62096 | H40: =SUM(H35:H39) -> 89515.2
B41: F. DEPRECIATION & AMORTISATION
...

Sheet P&L
B1: TOKENEQUITYX — PROFIT & LOSS STATEMENT
B2: All values USD. Green cells link from REVENUE and OPEX sheets. Negative = loss / cost.
B4: INCOME STATEMENT (USD) | C4: 2026A | D4: 2027E | E4: 2028E | F4: 2029E | G4: 2030E | H4: NOTES
B5: REVENUE
B6: Trading Fees | D6: =REVENUE!D13 -> 15000 | E6: =REVENUE!E13 -> 90000 | F6: =REVENUE!F13 -> 360000 | G6: =REVENUE!G13 -> 1200000 | H6: =REVENUE!H13 -> 3600000
B7: Issuance Fees | D7: =REVENUE!D14 -> 12500 | E7: =REVENUE!E14 -> 18750 | F7: =REVENUE!F14 -> 25000 | G7: =REVENUE!G14 -> 31250 | H7: =REVENUE!H14 -> 37500
B8: Annual Platform Fees | D8: =REVENUE!D15 -> 50000 | E8: =REVENUE!E15 -> 125000 | F8: =REVENUE!F15 -> 225000 | G8: =REVENUE!G15 -> 350000 | H8: =REVENUE!H15 -> 500000
B9: Valuation Services | D9: =REVENUE!D16 -> 20000 | E9: =REVENUE!E16 -> 50000 | F9: =REVENUE!F16 -> 90000 | G9: =REVENUE!G16 -> 140000 | H9: =REVENUE!H16 -> 200000
B10: KYC Onboarding Fees | D10: =REVENUE!D17 -> 25000 | E10: =REVENUE!E17 -> 75000 | F10: =REVENUE!F17 -> 175000 | G10: =REVENUE!G17 -> 325000 | H10: =REVENUE!H17 -> 650000
B11: White-Label Licensing | D11: =REVENUE!D18 -> 0 | E11: =REVENUE!E18 -> 100000 | F11: =REVENUE!F18 -> 250000 | G11: =REVENUE!G18 -> 500000 | H11: =REVENUE!H18 -> 900000
B12: Data & Analytics | D12: =REVENUE!D19 -> 0 | E12: =REVENUE!E19 -> 30000 | F12: =REVENUE!F19 -> 120000 | G12: =REVENUE!G19 -> 350000 | H12: =REVENUE!H19 -> 800000
B13: TOTAL REVENUE | D13: =SUM(D6:D12) -> 122500 | E13: =SUM(E6:E12) -> 488750 | F13: =SUM(F6:F12) -> 1245000 | G13: =SUM(G6:G12) -> 2896250 | H13: =SUM(H6:H12) -> 6687500
B14: OTHER INCOME
B15: IFC Technical Assistance Grant | D15: =REVENUE!D20 -> 80000 | E15: =REVENUE!E20 -> 0 | F15: =REVENUE!F20 -> 0 | G15: =REVENUE!G20 -> 0 | H15: =REVENUE!H20 -> 0 | I15: Year 1 only — non-recurring
B16: TOTAL OTHER INCOME | D16: =D15 -> 80000 | E16: =E15 -> 0 | F16: =F15 -> 0 | G16: =G15 -> 0 | H16: =H15 -> 0
B17: GROSS PROFIT / TOTAL INCOME | D17: =D13+D16 -> 202500 | E17: =E13+E16 -> 488750 | F17: =F13+F16 -> 1245000 | G17: =G13+G16 -> 2896250 | H17: =H13+H16 -> 6687500
B19: OPERATING EXPENSES
B20: People Costs | D20: =-OPEX!D15 -> -60750 | E20: =-OPEX!E15 -> -249000 | F20: =-OPEX!F15 -> -309000 | G20: =-OPEX!G15 -> -389000 | H20: =-OPEX!H15 -> -539000
B21: Technology Costs | D21: =-OPEX!D22 -> -32200 | E21: =-OPEX!E22 -> -37280 | F21: =-OPEX!F22 -> -46234 | G21: =-OPEX!G22 -> -56546.7 | H21: =-OPEX!H22 -> -68578.835
B22: Regulatory & Legal | D22: =-OPEX!D28 -> -93000 | E22: =-OPEX!E28 -> -47000 | F22: =-OPEX!F28 -> -56000 | G22: =-OPEX!G28 -> -68000 | H22: =-OPEX!H28 -> -84500
B23: Sales & Marketing | D23: =-OPEX!D33 -> -15000 | E23: =-OPEX!E33 -> -29250 | F23: =-OPEX!F33 -> -51875 | G23: =-OPEX!G33 -> -85312.5 | H23: =-OPEX!H33 -> -137968.75
B24: General & Administrative | D24: =-OPEX!D40 -> -21000 | E24: =-OPEX!E40 -> -30400 | F24: =-OPEX!F40 -> -43080 | G24: =-OPEX!G40 -> -62096 | H24: =-OPEX!H40 -> -89515.2
B25: TOTAL OPERATING EXPENSES | D25: =SUM(D20:D24) -> -221950 | E25: =SUM(E20:E24) -> -392930 | F25: =SUM(F20:F24) -> -506189 | G25: =SUM(G20:G24) -> -660955.2 | H25: =SUM(H20:H24) -> -919562.79
B27: EBITDA | D27: =D17+D25 -> -19450 | E27: =E17+E25 -> 95820 | F27: =F17+F25 -> 738811 | G27: =G17+G25 -> 2235294.8 | H27: =H17+H25 -> 5767937.2
B28: EBITDA Margin | D28: =IFERROR(D27/D13,"-") -> -0.15877551 | E28: =IFERROR(E27/E13,"-") -> 0.19605115 | F28: =IFERROR(F27/F13,"-") -> 0.59342249 | G28: =IFERROR(G27/G13,"-") -> 0.77178931 | H28: =IFERROR(H27/H13,"-") -> 0.86249528
B30: BELOW THE LINE
B31: Depreciation & Amortisation | D31: =-OPEX!D42 -> 0 | E31: =-OPEX!E42 -> -2788.5 | F31: =-OPEX!F42 -> -8588.4 | G31: =-OPEX!G42 -> -10657.02 | H31: =-OPEX!H42 -> -13366.401
B32: EBIT (Operating Profit) | D32: =D27+D31 -> -19450 | E32: =E27+E31 -> 93031.5 | F32: =F27+F31 -> 730222.6 | G32: =G27+G31 -> 2224637.8 | H32: =H27+H31 -> 5754570.8
B33: Interest Income / (Expense) | D33: 0 | E33: 0 | F33: 0 | G33: 0 | H33: 0
B34: PROFIT BEFORE TAX (PBT) | D34: =D32+D33 -> -19450 | E34: =E32+E33 -> 93031.5 | F34: =F32+F33 -> 730222.6 | G34: =G32+G33 -> 2224637.8 | H34: =H32+H33 -> 5754570.8
B35: Income Tax ({A(ASS_TAX_RATE)} rate) | D35: =IF(D34>0,-D34*ASSUMPTIONS!C81,0) -> 0 | E35: =IF(E34>0,-E34*ASSUMPTIONS!C81,0) -> -23257.875 | F35: =IF(F34>0,-F34*ASSUMPTIONS!C81,0) -> -182555.65 | G35: =IF(G34>0,-G34*ASSUMPTIONS!C81,0) -> -556159.44 | H35: =IF(H34>0,-H34*ASSUMPTIONS!C81,0) -> -1438642.7
B36: NET PROFIT / (LOSS) | D36: =D34+D35 -> -19450 | E36: =E34+E35 -> 69773.625 | F36: =F34+F35 -> 547666.95 | G36: =G34+G35 -> 1668478.3 | H36: =H34+H35 -> 4315928.1
B37: Net Profit Margin | D37: =IFERROR(D36/D13,"-") -> -0.15877551 | E37: =IFERROR(E36/E13,"-") -> 0.14275934 | F37: =IFERROR(F36/F13,"-") -> 0.43989313 | G37: =IFERROR(G36/G13,"-") -> 0.57608229 | H37: =IFERROR(H36/H13,"-") -> 0.64537243

Sheet CASH FLOW
B1: TOKENEQUITYX — CASH FLOW STATEMENT
B2: Indirect method. Links from P&L. Opening cash = closing cash of prior year.
B4: CASH FLOW STATEMENT (USD) | C4: 2026A | D4: 2027E | E4: 2028E | F4: 2029E | G4: 2030E | H4: NOTES
B5: A. OPERATING ACTIVITIES
B6: Net Profit / (Loss) | D6: ='P&L'!D36 -> -19450 | E6: ='P&L'!E36 -> 69773.625 | F6: ='P&L'!F36 -> 547666.95 | G6: ='P&L'!G36 -> 1668478.3 | H6: ='P&L'!H36 -> 4315928.1 | I6: From P&L
B7: Add: Depreciation & Amortisation | D7: =-'P&L'!D31 -> 0 | E7: =-'P&L'!E31 -> 2788.5 | F7: =-'P&L'!F31 -> 8588.4 | G7: =-'P&L'!G31 -> 10657.02 | H7: =-'P&L'!H31 -> 13366.401 | I7: D&A added back (non-cash)
B8: Changes in Working Capital | D8: =0 -> 0 | E8: =-'P&L'!E13*0.04 -> -19550 | F8: =-'P&L'!F13*0.04 -> -49800 | G8: =-'P&L'!G13*0.04 -> -115850 | H8: =-'P&L'!H13*0.04 -> -267500 | I8: ~4% of revenue increment — trade receivables and payables
B9: NET CASH FROM OPERATING ACTIVITIES | D9: =D6+D7+D8 -> -19450 | E9: =E6+E7+E8 -> 53012.125 | F9: =F6+F7+F8 -> 506455.35 | G9: =G6+G7+G8 -> 1563285.4 | H9: =H6+H7+H8 -> 4061794.5
B11: B. INVESTING ACTIVITIES
B12: Capital Expenditure (Capitalised Software) | D12: =-15000 -> -15000 | E12: =-20000 -> -20000 | F12: =-25000 -> -25000 | G12: =-35000 -> -35000 | H12: =-50000 -> -50000 | I12: Platform development capitalisation
B13: NET CASH FROM INVESTING ACTIVITIES | D13: =D12 -> -15000 | E13: =E12 -> -20000 | F13: =F12 -> -25000 | G13: =G12 -> -35000 | H13: =H12 -> -50000
B15: C. FINANCING ACTIVITIES
B16: Equity Capital Raised | D16: =150000 -> 150000 | E16: =0 -> 0 | F16: =0 -> 0 | G16: =0 -> 0 | H16: =0 -> 0 | I16: Year 1: Founder equity / IFC grant deployment for setup costs
B17: NET CASH FROM FINANCING ACTIVITIES | D17: =D16 -> 150000 | E17: =E16 -> 0 | F17: =F16 -> 0 | G17: =G16 -> 0 | H17: =H16 -> 0
B19: NET CHANGE IN CASH | D19: =D9+D13+D17 -> 115550 | E19: =E9+E13+E17 -> 33012.125 | F19: =F9+F13+F17 -> 481455.35 | G19: =G9+G13+G17 -> 1528285.4 | H19: =H9+H13+H17 -> 4011794.5
B20: Opening Cash Balance | D20: =0 -> 0 | E20: =D21 -> 115550 | F20: =E21 -> 148562.12 | G20: =F21 -> 630017.47 | H20: =G21 -> 2158302.8 | I20: Start of period cash
B21: CLOSING CASH BALANCE | D21: =D19+D20 -> 115550 | E21: =D21+E19 -> 148562.12 | F21: =E21+F19 -> 630017.47 | G21: =F21+G19 -> 2158302.8 | H21: =G21+H19 -> 6170097.3

Sheet SCENARIOS
B1: TOKENEQUITYX — SCENARIO COMPARISON
B2: Bear (60% of Base volumes) | Base (100%) | Bull (150%). Set scenario in ASSUMPTIONS!C to see dynamic P&L above.
C4: BEAR CASE (60% Vol) | H4: BASE CASE (100% Vol) | M4: BULL CASE (150% Vol)
B5: METRIC (USD) | C5: 2026A | D5: 2027E | E5: 2028E | F5: 2029E | G5: 2030E | H5: 2026A | I5: 2027E | J5: 2028E | K5: 2029E | L5: 2030E | M5: 2026A | N5: 2027E | O5: 2028E | P5: 2029E | Q5: 2030E
B6: Total Revenue | C6: ='P&L'!D13*ASSUMPTIONS!C85/MAX(0.001,IF(ASSUMPTIONS!C84="Bear",ASSUMPTIONS!C85,IF(ASSUMPTIONS!C84="Bull",ASSUMPTIONS!C86,1))) -> 73500 | D6: ='P&L'!E13*ASSUMPTIONS!C85/MAX(0.001,IF(ASSUMPTIONS!C84="Bear",ASSUMPTIONS!C85,IF(ASSUMPTIONS!C84="Bull",ASSUMPTIONS!C86,1))) -> 293250 | E6: ='P&L'!F13*ASSUMPTIONS!C85/MAX(0.001,IF(ASSUMPTIONS!C84="Bear",ASSUMPTIONS!C85,IF(ASSUMPTIONS!C84="Bull",ASSUMPTIONS!C86,1))) -> 747000 | F6: ='P&L'!G13*ASSUMPTIONS!C85/MAX(0.001,IF(ASSUMPTIONS!C84="Bear",ASSUMPTIONS!C85,IF(ASSUMPTIONS!C84="Bull",ASSUMPTIONS!C86,1))) -> 1737750 | G6: ='P&L'!H13*ASSUMPTIONS!C85/MAX(0.001,IF(ASSUMPTIONS!C84="Bear",ASSUMPTIONS!C85,IF(ASSUMPTIONS!C84="Bull",ASSUMPTIONS!C86,1))) -> 4012500 | H6: ='P&L'!D13 -> 122500 | I6: ='P&L'!E13 -> 488750 | J6: ='P&L'!F13 -> 1245000 | K6: ='P&L'!G13 -> 2896250 | L6: ='P&L'!H13 -> 6687500 | M6: ='P&L'!D13*ASSUMPTIONS!C86/MAX(0.001,IF(ASSUMPTIONS!C84="Bear",ASSUMPTIONS!C85,IF(ASSUMPTIONS!C84="Bull",ASSUMPTIONS!C86,1))) -> 183750 | N6: ='P&L'!E13*ASSUMPTIONS!C86/MAX(0.001,IF(ASSUMPTIONS!C84="Bear",ASSUMPTIONS!C85,IF(ASSUMPTIONS!C84="Bull",ASSUMPTIONS!C86,1))) -> 733125 | O6: ='P&L'!F13*ASSUMPTIONS!C86/MAX(0.001,IF(ASSUMPTIONS!C84="Bear",ASSUMPTIONS!C85,IF(ASSUMPTIONS!C84="Bull",ASSUMPTIONS!C86,1))) -> 1867500 | P6: ='P&L'!G13*ASSUMPTIONS!C86/MAX(0.001,IF(ASSUMPTIONS!C84="Bear",ASSUMPTIONS!C85,IF(ASSUMPTIONS!C84="Bull",ASSUMPTIONS!C86,1))) -> 4344375 | Q6: ='P&L'!H13*ASSUMPTIONS!C86/MAX(0.001,IF(ASSUMPTIONS!C84="Bear",ASSUMPTIONS!C85,IF(ASSUMPTIONS!C84="Bull",ASSUMPTIONS!C86,1))) -> 10031250
B7: Trading Fees
B8: Platform Fees
B9: Total OpEx | C9: ='P&L'!D44 -> 0 | D9: ='P&L'!E44 -> 0 | E9: ='P&L'!F44 -> 0 | F9: ='P&L'!G44 -> 0 | G9: ='P&L'!H44 -> 0 | H9: ='P&L'!D44 -> 0 | I9: ='P&L'!E44 -> 0 | J9: ='P&L'!F44 -> 0 | K9: ='P&L'!G44 -> 0 | L9: ='P&L'!H44 -> 0 | M9: ='P&L'!D44 -> 0 | N9: ='P&L'!E44 -> 0 | O9: ='P&L'!F44 -> 0 | P9: ='P&L'!G44 -> 0 | Q9: ='P&L'!H44 -> 0
B10: EBITDA | C10: ='P&L'!D27*ASSUMPTIONS!C85/MAX(0.001,IF(ASSUMPTIONS!C84="Bear",ASSUMPTIONS!C85,IF(ASSUMPTIONS!C84="Bull",ASSUMPTIONS!C86,1))) -> -11670 | D10: ='P&L'!E27*ASSUMPTIONS!C85/MAX(0.001,IF(ASSUMPTIONS!C84="Bear",ASSUMPTIONS!C85,IF(ASSUMPTIONS!C84="Bull",ASSUMPTIONS!C86,1))) -> 57492 | E10: ='P&L'!F27*ASSUMPTIONS!C85/MAX(0.001,IF(ASSUMPTIONS!C84="Bear",ASSUMPTIONS!C85,IF(ASSUMPTIONS!C84="Bull",ASSUMPTIONS!C86,1))) -> 443286.6 | F10: ='P&L'!G27*ASSUMPTIONS!C85/MAX(0.001,IF(ASSUMPTIONS!C84="Bear",ASSUMPTIONS!C85,IF(ASSUMPTIONS!C84="Bull",ASSUMPTIONS!C86,1))) -> 1341176.9 | G10: ='P&L'!H27*ASSUMPTIONS!C85/MAX(0.001,IF(ASSUMPTIONS!C84="Bear",ASSUMPTIONS!C85,IF(ASSUMPTIONS!C84="Bull",ASSUMPTIONS!C86,1))) -> 3460762.3 | H10: ='P&L'!D27 -> -19450 | I10: ='P&L'!E27 -> 95820 | J10: ='P&L'!F27 -> 738811 | K10: ='P&L'!G27 -> 2235294.8 | L10: ='P&L'!H27 -> 5767937.2 | M10: ='P&L'!D27*ASSUMPTIONS!C86/MAX(0.001,IF(ASSUMPTIONS!C84="Bear",ASSUMPTIONS!C85,IF(ASSUMPTIONS!C84="Bull",ASSUMPTIONS!C86,1))) -> -29175 | N10: ='P&L'!E27*ASSUMPTIONS!C86/MAX(0.001,IF(ASSUMPTIONS!C84="Bear",ASSUMPTIONS!C85,IF(ASSUMPTIONS!C84="Bull",ASSUMPTIONS!C86,1))) -> 143730 | O10: ='P&L'!F27*ASSUMPTIONS!C86/MAX(0.001,IF(ASSUMPTIONS!C84="Bear",ASSUMPTIONS!C85,IF(ASSUMPTIONS!C84="Bull",ASSUMPTIONS!C86,1))) -> 1108216.5 | P10: ='P&L'!G27*ASSUMPTIONS!C86/MAX(0.001,IF(ASSUMPTIONS!C84="Bear",ASSUMPTIONS!C85,IF(ASSUMPTIONS!C84="Bull",ASSUMPTIONS!C86,1))) -> 3352942.2 | Q10: ='P&L'!H27*ASSUMPTIONS!C86/MAX(0.001,IF(ASSUMPTIONS!C84="Bear",ASSUMPTIONS!C85,IF(ASSUMPTIONS!C84="Bull",ASSUMPTIONS!C86,1))) -> 8651905.8
B11: EBITDA Margin | C11: ='P&L'!D28 -> -0.15877551 | D11: ='P&L'!E28 -> 0.19605115 | E11: ='P&L'!F28 -> 0.59342249 | F11: ='P&L'!G28 -> 0.77178931 | G11: ='P&L'!H28 -> 0.86249528 | H11: ='P&L'!D28 -> -0.15877551 | I11: ='P&L'!E28 -> 0.19605115 | J11: ='P&L'!F28 -> 0.59342249 | K11: ='P&L'!G28 -> 0.77178931 | L11: ='P&L'!H28 -> 0.86249528 | M11: ='P&L'!D28 -> -0.15877551 | N11: ='P&L'!E28 -> 0.19605115 | O11: ='P&L'!F28 -> 0.59342249 | P11: ='P&L'!G28 -> 0.77178931 | Q11: ='P&L'!H28 -> 0.86249528
B12: Net Profit / (Loss) | C12: ='P&L'!D36*ASSUMPTIONS!C85/MAX(0.001,IF(ASSUMPTIONS!C84="Bear",ASSUMPTIONS!C85,IF(ASSUMPTIONS!C84="Bull",ASSUMPTIONS!C86,1))) -> -11670 | D12: ='P&L'!E36*ASSUMPTIONS!C85/MAX(0.001,IF(ASSUMPTIONS!C84="Bear",ASSUMPTIONS!C85,IF(ASSUMPTIONS!C84="Bull",ASSUMPTIONS!C86,1))) -> 41864.175 | E12: ='P&L'!F36*ASSUMPTIONS!C85/MAX(0.001,IF(ASSUMPTIONS!C84="Bear",ASSUMPTIONS!C85,IF(ASSUMPTIONS!C84="Bull",ASSUMPTIONS!C86,1))) -> 328600.17 | F12: ='P&L'!G36*ASSUMPTIONS!C85/MAX(0.001,IF(ASSUMPTIONS!C84="Bear",ASSUMPTIONS!C85,IF(ASSUMPTIONS!C84="Bull",ASSUMPTIONS!C86,1))) -> 1001087 | G12: ='P&L'!H36*ASSUMPTIONS!C85/MAX(0.001,IF(ASSUMPTIONS!C84="Bear",ASSUMPTIONS!C85,IF(ASSUMPTIONS!C84="Bull",ASSUMPTIONS!C86,1))) -> 2589556.9 | H12: ='P&L'!D36 -> -19450 | I12: ='P&L'!E36 -> 69773.625 | J12: ='P&L'!F36 -> 547666.95 | K12: ='P&L'!G36 -> 1668478.3 | L12: ='P&L'!H36 -> 4315928.1 | M12: ='P&L'!D36*ASSUMPTIONS!C86/MAX(0.001,IF(ASSUMPTIONS!C84="Bear",ASSUMPTIONS!C85,IF(ASSUMPTIONS!C84="Bull",ASSUMPTIONS!C86,1))) -> -29175 | N12: ='P&L'!E36*ASSUMPTIONS!C86/MAX(0.001,IF(ASSUMPTIONS!C84="Bear",ASSUMPTIONS!C85,IF(ASSUMPTIONS!C84="Bull",ASSUMPTIONS!C86,1))) -> 104660.44 | O12: ='P&L'!F36*ASSUMPTIONS!C86/MAX(0.001,IF(ASSUMPTIONS!C84="Bear",ASSUMPTIONS!C85,IF(ASSUMPTIONS!C84="Bull",ASSUMPTIONS!C86,1))) -> 821500.43 | P12: ='P&L'!G36*ASSUMPTIONS!C86/MAX(0.001,IF(ASSUMPTIONS!C84="Bear",ASSUMPTIONS!C85,IF(ASSUMPTIONS!C84="Bull",ASSUMPTIONS!C86,1))) -> 2502717.5 | Q12: ='P&L'!H36*ASSUMPTIONS!C86/MAX(0.001,IF(ASSUMPTIONS!C84="Bear",ASSUMPTIONS!C85,IF(ASSUMPTIONS!C84="Bull",ASSUMPTIONS!C86,1))) -> 6473892.2
B13: Net Margin | C13: ='P&L'!D37 -> -0.15877551 | D13: ='P&L'!E37 -> 0.14275934 | E13: ='P&L'!F37 -> 0.43989313 | F13: ='P&L'!G37 -> 0.57608229 | G13: ='P&L'!H37 -> 0.64537243 | H13: ='P&L'!D37 -> -0.15877551 | I13: ='P&L'!E37 -> 0.14275934 | J13: ='P&L'!F37 -> 0.43989313 | K13: ='P&L'!G37 -> 0.57608229 | L13: ='P&L'!H37 -> 0.64537243 | M13: ='P&L'!D37 -> -0.15877551 | N13: ='P&L'!E37 -> 0.14275934 | O13: ='P&L'!F37 -> 0.43989313 | P13: ='P&L'!G37 -> 0.57608229 | Q13: ='P&L'!H37 -> 0.64537243
B14: Closing Cash | C14: ='P&L'!D21*ASSUMPTIONS!C85/MAX(0.001,IF(ASSUMPTIONS!C84="Bear",ASSUMPTIONS!C85,IF(ASSUMPTIONS!C84="Bull",ASSUMPTIONS!C86,1))) -> -19320 | D14: ='P&L'!E21*ASSUMPTIONS!C85/MAX(0.001,IF(ASSUMPTIONS!C84="Bear",ASSUMPTIONS!C85,IF(ASSUMPTIONS!C84="Bull",ASSUMPTIONS!C86,1))) -> -22368 | E14: ='P&L'!F21*ASSUMPTIONS!C85/MAX(0.001,IF(ASSUMPTIONS!C84="Bear",ASSUMPTIONS!C85,IF(ASSUMPTIONS!C84="Bull",ASSUMPTIONS!C86,1))) -> -27740.4 | F14: ='P&L'!G21*ASSUMPTIONS!C85/MAX(0.001,IF(ASSUMPTIONS!C84="Bear",ASSUMPTIONS!C85,IF(ASSUMPTIONS!C84="Bull",ASSUMPTIONS!C86,1))) -> -33928.02 | G14: ='P&L'!H21*ASSUMPTIONS!C85/MAX(0.001,IF(ASSUMPTIONS!C84="Bear",ASSUMPTIONS!C85,IF(ASSUMPTIONS!C84="Bull",ASSUMPTIONS!C86,1))) -> -41147.301 | H14: ='P&L'!D21 -> -32200 | I14: ='P&L'!E21 -> -37280 | J14: ='P&L'!F21 -> -46234 | K14: ='P&L'!G21 -> -56546.7 | L14: ='P&L'!H21 -> -68578.835 | M14: ='P&L'!D21*ASSUMPTIONS!C86/MAX(0.001,IF(ASSUMPTIONS!C84="Bear",ASSUMPTIONS!C85,IF(ASSUMPTIONS!C84="Bull",ASSUMPTIONS!C86,1))) -> -48300 | N14: ='P&L'!E21*ASSUMPTIONS!C86/MAX(0.001,IF(ASSUMPTIONS!C84="Bear",ASSUMPTIONS!C85,IF(ASSUMPTIONS!C84="Bull",ASSUMPTIONS!C86,1))) -> -55920 | O14: ='P&L'!F21*ASSUMPTIONS!C86/MAX(0.001,IF(ASSUMPTIONS!C84="Bear",ASSUMPTIONS!C85,IF(ASSUMPTIONS!C84="Bull",ASSUMPTIONS!C86,1))) -> -69351 | P14: ='P&L'!G21*ASSUMPTIONS!C86/MAX(0.001,IF(ASSUMPTIONS!C84="Bear",ASSUMPTIONS!C85,IF(ASSUMPTIONS!C84="Bull",ASSUMPTIONS!C86,1))) -> -84820.05 | Q14: ='P&L'!H21*ASSUMPTIONS!C86/MAX(0.001,IF(ASSUMPTIONS!C84="Bear",ASSUMPTIONS!C85,IF(ASSUMPTIONS!C84="Bull",ASSUMPTIONS!C86,1))) -> -102868.25

Sheet VALUATION
B1: TOKENEQUITYX — VALUATION MODEL
B2: DCF valuation + exit multiples + sensitivity tables. All assumptions from ASSUMPTIONS sheet.
B4: A. DISCOUNTED CASH FLOW VALUATION
B5: DCF INPUTS | C5: VALUE | D5: SOURCE
B6: WACC (Discount Rate) | C6: =ASSUMPTIONS!C77 -> 0.18 | D6: ASSUMPTIONS!C77
B7: Terminal Growth Rate | C7: =ASSUMPTIONS!C78 -> 0.04 | D7: ASSUMPTIONS!C78
B8: Projection Period (years) | C8: =5 -> 5 | D8: 5-year explicit forecast
B9: Terminal Year EBITDA | C9: ='P&L'!H27 -> 5767937.2 | D9: P&L Year 5 EBITDA
B10: Terminal Year Revenue | C10: ='P&L'!H13 -> 6687500 | D10: P&L Year 5 Revenue
B12: B. FREE CASH FLOW TO FIRM (FCFF)
B13: FCFF BUILD (USD) | C13: 2026A | D13: 2027E | E13: 2028E | F13: 2029E | G13: 2030E
B14: EBIT | C14: ='P&L'!D32 -> -19450 | D14: ='P&L'!E32 -> 93031.5 | E14: ='P&L'!F32 -> 730222.6 | F14: ='P&L'!G32 -> 2224637.8 | G14: ='P&L'!H32 -> 5754570.8
B15: Less: Tax on EBIT | C15: =IF('P&L'!D32>0,-'P&L'!D32*ASSUMPTIONS!C81,0) -> 0 | D15: =IF('P&L'!E32>0,-'P&L'!E32*ASSUMPTIONS!C81,0) -> -23257.875 | E15: =IF('P&L'!F32>0,-'P&L'!F32*ASSUMPTIONS!C81,0) -> -182555.65 | F15: =IF('P&L'!G32>0,-'P&L'!G32*ASSUMPTIONS!C81,0) -> -556159.44 | G15: =IF('P&L'!H32>0,-'P&L'!H32*ASSUMPTIONS!C81,0) -> -1438642.7
B16: Add: D&A | C16: =-'P&L'!D31 -> 0 | D16: =-'P&L'!E31 -> 2788.5 | E16: =-'P&L'!F31 -> 8588.4 | F16: =-'P&L'!G31 -> 10657.02 | G16: =-'P&L'!H31 -> 13366.401
B17: Less: CapEx | C17: ='CASH FLOW'!D12 -> -15000 | D17: ='CASH FLOW'!E12 -> -20000 | E17: ='CASH FLOW'!F12 -> -25000 | F17: ='CASH FLOW'!G12 -> -35000 | G17: ='CASH FLOW'!H12 -> -50000
B18: Less: ΔWC | C18: ='CASH FLOW'!D8 -> 0 | D18: ='CASH FLOW'!E8 -> -19550 | E18: ='CASH FLOW'!F8 -> -49800 | F18: ='CASH FLOW'!G8 -> -115850 | G18: ='CASH FLOW'!H8 -> -267500
B19: FREE CASH FLOW (FCFF) | C19: =C14+C15+C16+C17+C18 -> -34450 | D19: =D14+D15+D16+D17+D18 -> 33012.125 | E19: =E14+E15+E16+E17+E18 -> 481455.35 | F19: =F14+F15+F16+F17+F18 -> 1528285.4 | G19: =G14+G15+G16+G17+G18 -> 4011794.5
B20: Discount Factor | C20: =1/(1+ASSUMPTIONS!C77)^1 -> 0.84745763 | D20: =1/(1+ASSUMPTIONS!C77)^2 -> 0.71818443 | E20: =1/(1+ASSUMPTIONS!C77)^3 -> 0.60863087 | F20: =1/(1+ASSUMPTIONS!C77)^4 -> 0.51578888 | G20: =1/(1+ASSUMPTIONS!C77)^5 -> 0.43710922
B21: PV of FCFF | C21: =C19*C20 -> -29194.915 | D21: =D19*D20 -> 23708.794 | E21: =E19*E20 -> 293028.59 | F21: =F19*F20 -> 788272.58 | G21: =G19*G20 -> 1753592.4
B23: C. TERMINAL VALUE AND EQUITY VALUE
B24: Sum of PV of FCFFs | C24: =SUM(C21:G21) -> 2829407.4
B25: Terminal FCFF (Year 5 × (1+g)) | C25: =H19*(1+ASSUMPTIONS!C78) -> 0
B26: Terminal Value (Gordon Growth Model) | C26: =C25/(ASSUMPTIONS!C77-ASSUMPTIONS!C78) -> 0
B27: PV of Terminal Value | C27: =C26/(1+ASSUMPTIONS!C77)^5 -> 0
B28: Enterprise Value (DCF) | C28: =C24+C27 -> 2829407.4
B29: Less: Net Debt / (Cash) | C29: =0 -> 0
B30: EQUITY VALUE (DCF) | C30: =C28-C29 -> 2829407.4
B32: D. EXIT MULTIPLE VALUATION
B33: METRIC | C33: YEAR 5 VALUE | D33: MULTIPLE | E33: ENTERPRISE VALUE
B34: EV / Revenue | C34: ='P&L'!H13 -> 6687500 | D34: =ASSUMPTIONS!C79 -> 8 | E34: =C34*D34 -> 53500000
B35: EV / EBITDA | C35: ='P&L'!H27 -> 5767937.2 | D35: =ASSUMPTIONS!C80 -> 20 | E35: =C35*D35 -> 1.1535874e+08
B37: E. VALUATION SUMMARY
B38: DCF Equity Value | C38: =C30 -> 2829407.4
B39: EV / Revenue Multiple | C39: =E34 -> 53500000
B40: EV / EBITDA Multiple | C40: =E35 -> 1.1535874e+08
B41: BLENDED EQUITY VALUATION | C41: =AVERAGE(C38:C40) -> 57229384
B43: F. SENSITIVITY ANALYSIS — EQUITY VALUE vs WACC & TERMINAL GROWTH
B44: WACC ↓ / TGR → | C44: 0.02 | D44: 0.03 | E44: 0.04 | F44: 0.05 | G44: 0.06
B45: 0.12 | C45: =MAX(0,C24+C25/MAX(0.001,0.12-0.02)/(1+0.12)^5-C29) -> 2829407.4 | D45: =MAX(0,C24+C25/MAX(0.001,0.12-0.03)/(1+0.12)^5-C29) -> 2829407.4 | E45: =MAX(0,C24+C25/MAX(0.001,0.12-0.04)/(1+0.12)^5-C29) -> 2829407.4 | F45: =MAX(0,C24+C25/MAX(0.001,0.12-0.05)/(1+0.12)^5-C29) -> 2829407.4 | G45: =MAX(0,C24+C25/MAX(0.001,0.12-0.06)/(1+0.12)^5-C29) -> 2829407.4
B46: 0.15 | C46: =MAX(0,C24+C25/MAX(0.001,0.15-0.02)/(1+0.15)^5-C29) -> 2829407.4 | D46: =MAX(0,C24+C25/MAX(0.001,0.15-0.03)/(1+0.15)^5-C29) -> 2829407.4 | E46: =MAX(0,C24+C25/MAX(0.001,0.15-0.04)/(1+0.15)^5-C29) -> 2829407.4 | F46: =MAX(0,C24+C25/MAX(0.001,0.15-0.05)/(1+0.15)^5-C29) -> 2829407.4 | G46: =MAX(0,C24+C25/MAX(0.001,0.15-0.06)/(1+0.15)^5-C29) -> 2829407.4
...

Sheet KPIs
B1: TOKENEQUITYX — KEY PERFORMANCE INDICATORS
B3: KPI | C3: 2026A | D3: 2027E | E3: 2028E | F3: 2029E | G3: 2030E | H3: NOTES
B4: A. PLATFORM OPERATIONAL KPIs
B5: Listed Assets (EOP) | D5: =ASSUMPTIONS!C11 -> 10 | E5: =ASSUMPTIONS!C12 -> 35 | F5: =ASSUMPTIONS!C13 -> 80 | G5: =ASSUMPTIONS!C14 -> 150 | H5: =ASSUMPTIONS!C15 -> 250 | I5: End of period listed assets
B6: Registered Investors (EOP) | D6: =ASSUMPTIONS!C17 -> 500 | E6: =ASSUMPTIONS!C18 -> 2500 | F6: =ASSUMPTIONS!C19 -> 8000 | G6: =ASSUMPTIONS!C20 -> 20000 | H6: =ASSUMPTIONS!C21 -> 45000 | I6: End of period total investors
B7: Monthly Trading Volume (USD) | D7: =ASSUMPTIONS!C23 -> 250000 | E7: =ASSUMPTIONS!C24 -> 1500000 | F7: =ASSUMPTIONS!C25 -> 6000000 | G7: =ASSUMPTIONS!C26 -> 20000000 | H7: =ASSUMPTIONS!C27 -> 60000000 | I7: Monthly average trading volume
B8: Annual Trading Volume (USD) | D8: =ASSUMPTIONS!C23*12 -> 3000000 | E8: =ASSUMPTIONS!C24*12 -> 18000000 | F8: =ASSUMPTIONS!C25*12 -> 72000000 | G8: =ASSUMPTIONS!C26*12 -> 240000000 | H8: =ASSUMPTIONS!C27*12 -> 720000000 | I8: Annual aggregate
B9: Assets per Employee (approx.) | D9: =0 -> 0 | E9: =ASSUMPTIONS!C12/8 -> 4.375 | F9: =ASSUMPTIONS!C13/12 -> 6.6666667 | G9: =ASSUMPTIONS!C14/18 -> 8.3333333 | H9: =ASSUMPTIONS!C15/25 -> 10 | I9: Operational efficiency metric
B10: B. FINANCIAL KPIs
B11: Total Revenue (USD) | D11: ='P&L'!D13 -> 122500 | E11: ='P&L'!E13 -> 488750 | F11: ='P&L'!F13 -> 1245000 | G11: ='P&L'!G13 -> 2896250 | H11: ='P&L'!H13 -> 6687500
B12: Revenue per Listed Asset (USD) | D12: =IFERROR('P&L'!D13/ASSUMPTIONS!C11,0) -> 12250 | E12: =IFERROR('P&L'!E13/ASSUMPTIONS!C12,0) -> 13964.286 | F12: =IFERROR('P&L'!F13/ASSUMPTIONS!C13,0) -> 15562.5 | G12: =IFERROR('P&L'!G13/ASSUMPTIONS!C14,0) -> 19308.333 | H12: =IFERROR('P&L'!H13/ASSUMPTIONS!C15,0) -> 26750 | I12: Revenue efficiency per asset
B13: Revenue per Investor (USD) | D13: =IFERROR('P&L'!D13/ASSUMPTIONS!C17,0) -> 245 | E13: =IFERROR('P&L'!E13/ASSUMPTIONS!C18,0) -> 195.5 | F13: =IFERROR('P&L'!F13/ASSUMPTIONS!C19,0) -> 155.625 | G13: =IFERROR('P&L'!G13/ASSUMPTIONS!C20,0) -> 144.8125 | H13: =IFERROR('P&L'!H13/ASSUMPTIONS!C21,0) -> 148.61111 | I13: Average revenue per investor
B14: EBITDA (USD) | D14: ='P&L'!D27 -> -19450 | E14: ='P&L'!E27 -> 95820 | F14: ='P&L'!F27 -> 738811 | G14: ='P&L'!G27 -> 2235294.8 | H14: ='P&L'!H27 -> 5767937.2
B15: EBITDA Margin | D15: ='P&L'!D28 -> -0.15877551 | E15: ='P&L'!E28 -> 0.19605115 | F15: ='P&L'!F28 -> 0.59342249 | G15: ='P&L'!G28 -> 0.77178931 | H15: ='P&L'!H28 -> 0.86249528
B16: Net Profit / (Loss) (USD) | D16: ='P&L'!D36 -> -19450 | E16: ='P&L'!E36 -> 69773.625 | F16: ='P&L'!F36 -> 547666.95 | G16: ='P&L'!G36 -> 1668478.3 | H16: ='P&L'!H36 -> 4315928.1
B17: Net Profit Margin | D17: ='P&L'!D37 -> -0.15877551 | E17: ='P&L'!E37 -> 0.14275934 | F17: ='P&L'!F37 -> 0.43989313 | G17: ='P&L'!G37 -> 0.57608229 | H17: ='P&L'!H37 -> 0.64537243
B18: Closing Cash Balance (USD) | D18: ='CASH FLOW'!D21 -> 115550 | E18: ='CASH FLOW'!E21 -> 148562.12 | F18: ='CASH FLOW'!F21 -> 630017.47 | G18: ='CASH FLOW'!G21 -> 2158302.8 | H18: ='CASH FLOW'!H21 -> 6170097.3
B19: C. UNIT ECONOMICS
B20: Trading Fee per USD Volume | D20: =ASSUMPTIONS!C30 -> 0.005 | E20: =ASSUMPTIONS!C30 -> 0.005 | F20: =ASSUMPTIONS!C30 -> 0.005 | G20: =ASSUMPTIONS!C30 -> 0.005 | H20: =ASSUMPTIONS!C30 -> 0.005 | I20: Fixed rate — 0.50%
B21: Platform Fee Revenue per Asset | D21: =ASSUMPTIONS!C33 -> 5000 | E21: =ASSUMPTIONS!C33 -> 5000 | F21: =ASSUMPTIONS!C33 -> 5000 | G21: =ASSUMPTIONS!C33 -> 5000 | H21: =ASSUMPTIONS!C33 -> 5000 | I21: Fixed USD 5,000 per listed asset p.a.
B22: Blended Revenue per New Investor | D22: =IFERROR(REVENUE!D13/MAX(1,ASSUMPTIONS!C17),0) -> 30 | E22: =IFERROR(REVENUE!E13/MAX(1,ASSUMPTIONS!C18),0) -> 36 | F22: =IFERROR(REVENUE!F13/MAX(1,ASSUMPTIONS!C19),0) -> 45 | G22: =IFERROR(REVENUE!G13/MAX(1,ASSUMPTIONS!C20),0) -> 60 | H22: =IFERROR(REVENUE!H13/MAX(1,ASSUMPTIONS!C21),0) -> 80 | I22: Trading fee revenue per registered investor
B23: Customer Acquisition Cost (est.) | D23: =IFERROR(OPEX!D33/MAX(1,REVENUE!D9),0) -> 30 | E23: =IFERROR(OPEX!E33/MAX(1,REVENUE!E9),0) -> 14.625 | F23: =IFERROR(OPEX!F33/MAX(1,REVENUE!F9),0) -> 9.4318182 | G23: =IFERROR(OPEX!G33/MAX(1,REVENUE!G9),0) -> 7.109375 | H23: =IFERROR(OPEX!H33/MAX(1,REVENUE!H9),0) -> 5.51875 | I23: Marketing spend / new investors

Sheet CHARTS
B1: TOKENEQUITYX — VISUAL SUMMARY
B3: CHART DATA
B4: METRIC | C4: 2026A | D4: 2027E | E4: 2028E | F4: 2029E | G4: 2030E
B5: Total Revenue | C5: ='P&L'!D13 -> 122500 | D5: ='P&L'!E13 -> 488750 | E5: ='P&L'!F13 -> 1245000 | F5: ='P&L'!G13 -> 2896250 | G5: ='P&L'!H13 -> 6687500
B6: EBITDA | C6: ='P&L'!D27 -> -19450 | D6: ='P&L'!E27 -> 95820 | E6: ='P&L'!F27 -> 738811 | F6: ='P&L'!G27 -> 2235294.8 | G6: ='P&L'!H27 -> 5767937.2
B7: Net Profit | C7: ='P&L'!D36 -> -19450 | D7: ='P&L'!E36 -> 69773.625 | E7: ='P&L'!F36 -> 547666.95 | F7: ='P&L'!G36 -> 1668478.3 | G7: ='P&L'!H36 -> 4315928.1
B8: Trading Fees | C8: =REVENUE!D13 -> 15000 | D8: =REVENUE!E13 -> 90000 | E8: =REVENUE!F13 -> 360000 | F8: =REVENUE!G13 -> 1200000 | G8: =REVENUE!H13 -> 3600000
B9: Platform Fees | C9: =REVENUE!D15 -> 50000 | D9: =REVENUE!E15 -> 125000 | E9: =REVENUE!F15 -> 225000 | F9: =REVENUE!G15 -> 350000 | G9: =REVENUE!H15 -> 500000
B10: White-Label | C10: =REVENUE!D18 -> 0 | D10: =REVENUE!E18 -> 100000 | E10: =REVENUE!F18 -> 250000 | F10: =REVENUE!G18 -> 500000 | G10: =REVENUE!H18 -> 900000
B11: Total OpEx | C11: =OPEX!D44 -> 221950 | D11: =OPEX!E44 -> 395718.5 | E11: =OPEX!F44 -> 514777.4 | F11: =OPEX!G44 -> 671612.22 | G11: =OPEX!H44 -> 932929.19
B12: Closing Cash | C12: ='CASH FLOW'!D21 -> 115550 | D12: ='CASH FLOW'!E21 -> 148562.12 | E12: ='CASH FLOW'!F21 -> 630017.47 | F12: ='CASH FLOW'!G21 -> 2158302.8 | G12: ='CASH FLOW'!H21 -> 6170097.3

Sheet BALANCE SHEET
B1: TOKENEQUITYX — BALANCE SHEET
B2: Simplified balance sheet linking from Cash Flow and P&L. All USD.
B4: BALANCE SHEET (USD) | C4: 2026A | D4: 2027E | E4: 2028E | F4: 2029E | G4: 2030E | H4: NOTES
B5: ASSETS
B6: Cash & Cash Equivalents | D6: ='CASH FLOW'!D21 -> 115550 | E6: ='CASH FLOW'!E21 -> 148562.12 | F6: ='CASH FLOW'!F21 -> 630017.47 | G6: ='CASH FLOW'!G21 -> 2158302.8 | H6: ='CASH FLOW'!H21 -> 6170097.3
B7: Trade Receivables | D7: ='P&L'!D13*0.04 -> 4900 | E7: ='P&L'!E13*0.04 -> 19550 | F7: ='P&L'!F13*0.04 -> 49800 | G7: ='P&L'!G13*0.04 -> 115850 | H7: ='P&L'!H13*0.04 -> 267500
B8: Other Current Assets | D8: =5000 -> 5000 | E8: =8000 -> 8000 | F8: =12000 -> 12000 | G8: =18000 -> 18000 | H8: =25000 -> 25000
B9: Total Current Assets | D9: =SUM(D6:D8) -> 125450 | E9: =SUM(E6:E8) -> 176112.12 | F9: =SUM(F6:F8) -> 691817.47 | G9: =SUM(G6:G8) -> 2292152.8 | H9: =SUM(H6:H8) -> 6462597.3
B10: Intangible Assets (Net) | D10: =15000 -> 15000 | E10: =28000 -> 28000 | F10: =40000 -> 40000 | G10: =55000 -> 55000 | H10: =75000 -> 75000
B11: Capitalised Software | D11: ='CASH FLOW'!D12*-1 -> 15000 | E11: ='CASH FLOW'!E12*-1 -> 20000 | F11: ='CASH FLOW'!F12*-1 -> 25000 | G11: ='CASH FLOW'!G12*-1 -> 35000 | H11: ='CASH FLOW'!H12*-1 -> 50000
B12: Total Non-Current Assets | D12: =SUM(D10:D11) -> 30000 | E12: =SUM(E10:E11) -> 48000 | F12: =SUM(F10:F11) -> 65000 | G12: =SUM(G10:G11) -> 90000 | H12: =SUM(H10:H11) -> 125000
B13: TOTAL ASSETS | D13: =D9+D12 -> 155450 | E13: =E9+E12 -> 224112.12 | F13: =F9+F12 -> 756817.47 | G13: =G9+G12 -> 2382152.8 | H13: =H9+H12 -> 6587597.3
B15: LIABILITIES & EQUITY
B16: Trade & Other Payables | D16: =8000 -> 8000 | E16: =15000 -> 15000 | F16: =25000 -> 25000 | G16: =40000 -> 40000 | H16: =60000 -> 60000
B17: Tax Payable | D17: =IF('P&L'!D36>0,'P&L'!D36*0.1,0) -> 0 | E17: =IF('P&L'!E36>0,'P&L'!E36*0.1,0) -> 6977.3625 | F17: =IF('P&L'!F36>0,'P&L'!F36*0.1,0) -> 54766.695 | G17: =IF('P&L'!G36>0,'P&L'!G36*0.1,0) -> 166847.83 | H17: =IF('P&L'!H36>0,'P&L'!H36*0.1,0) -> 431592.81
B18: Total Current Liabilities | D18: =SUM(D16:D17) -> 8000 | E18: =SUM(E16:E17) -> 21977.362 | F18: =SUM(F16:F17) -> 79766.695 | G18: =SUM(G16:G17) -> 206847.83 | H18: =SUM(H16:H17) -> 491592.81
B19: Share Capital | D19: =100 -> 100 | E19: =100 -> 100 | F19: =100 -> 100 | G19: =100 -> 100 | H19: =100 -> 100
B20: Retained Earnings | D20: ='P&L'!D36 -> -19450 | E20: ='P&L'!E36 -> 69773.625 | F20: ='P&L'!F36 -> 547666.95 | G20: ='P&L'!G36 -> 1668478.3 | H20: ='P&L'!H36 -> 4315928.1
B21: Equity Capital Raised | D21: =150000 -> 150000 | E21: =0 -> 0 | F21: =0 -> 0 | G21: =0 -> 0 | H21: =0 -> 0
B22: Total Equity | D22: =SUM(D19:D21) -> 130650 | E22: =SUM(E19:E21) -> 69873.625 | F22: =SUM(F19:F21) -> 547766.95 | G22: =SUM(G19:G21) -> 1668578.3 | H22: =SUM(H19:H21) -> 4316028.1
B23: TOTAL LIABILITIES & EQUITY | D23: =D18+D22 -> 138650 | E23: =E18+E22 -> 91850.988 | F23: =F18+F22 -> 627533.65 | G23: =G18+G22 -> 1875426.2 | H23: =H18+H22 -> 4807620.9
B24: BALANCE CHECK (Assets - Liab&Eq) | D24: =D13-D23 -> 16800 | E24: =E13-E23 -> 132261.14 | F24: =F13-F23 -> 129283.83 | G24: =G13-G23 -> 506726.66 | H24: =H13-H23 -> 1779976.4
